<?xml version="1.0" ?>
<!-- =================================================================================== -->
<!-- |    This document was autogenerated by xacro from ./gem.urdf.xacro               | -->
<!-- |    EDITING THIS FILE BY HAND IS NOT RECOMMENDED                                 | -->
<!-- =================================================================================== -->
<robot name="gem">
  <gazebo reference="right_steering_hinge_link">
    <mu1>0.9</mu1>
    <material>Gazebo/Blue</material>
  </gazebo>
  <gazebo reference="left_steering_hinge_link">
    <mu1>0.9</mu1>
    <material>Gazebo/Blue</material>
  </gazebo>
  <gazebo reference="front_left_wheel_link">
    <mu1>0.9</mu1>
    <mu2>0.9</mu2>
    <minDepth>0.005</minDepth>
    <kp>1e8</kp>
    <material>Gazebo/Black</material>
  </gazebo>
  <gazebo reference="front_right_wheel_link">
    <mu1>0.9</mu1>
    <mu2>0.9</mu2>
    <minDepth>0.005</minDepth>
    <kp>1e8</kp>
    <material>Gazebo/Black</material>
  </gazebo>
  <gazebo reference="right_fixed_hinge_link">
    <material>Gazebo/Red</material>
  </gazebo>
  <gazebo reference="left_fixed_hinge_link">
    <material>Gazebo/Red</material>
  </gazebo>
  <gazebo reference="rear_left_wheel_link">
    <mu1>0.9</mu1>
    <mu2>0.9</mu2>
    <minDepth>0.005</minDepth>
    <kp>1e8</kp>
    <material>Gazebo/Black</material>
  </gazebo>
  <gazebo reference="rear_right_wheel_link">
    <mu1>0.9</mu1>
    <mu2>0.9</mu2>
    <minDepth>0.005</minDepth>
    <kp>1e8</kp>
    <material>Gazebo/Black</material>
  </gazebo>
  <!-- colors used by Gazebo -->
  <gazebo reference="base_link">
    <material>Gazebo/White</material>
  </gazebo>
  <gazebo reference="chair_link">
    <material>Gazebo/Grey</material>
  </gazebo>
  <gazebo reference="door_link">
    <material>Gazebo/White</material>
  </gazebo>
  <gazebo reference="front_camera_link">
    <material>Gazebo/Black</material>
  </gazebo>
  <gazebo reference="front_rack_link">
    <material>Gazebo/Black</material>
  </gazebo>
  <gazebo reference="rear_rack_link">
    <material>Gazebo/Black</material>
  </gazebo>
  <gazebo reference="top_rack_link">
    <material>Gazebo/Black</material>
  </gazebo>
  <gazebo reference="front_left_emergency_button_link">
    <material>Gazebo/Red</material>
  </gazebo>
  <gazebo reference="front_right_emergency_button_link">
    <material>Gazebo/Red</material>
  </gazebo>
  <gazebo reference="rear_left_emergency_button_link">
    <material>Gazebo/Red</material>
  </gazebo>
  <gazebo reference="rear_right_emergency_button_link">
    <material>Gazebo/Red</material>
  </gazebo>
  <gazebo reference="rear_left_light_link">
    <material>Gazebo/Red</material>
  </gazebo>
  <gazebo reference="rear_right_light_link">
    <material>Gazebo/Red</material>
  </gazebo>
  <gazebo reference="rear_light_bar_link">
    <material>Gazebo/Red</material>
  </gazebo>
  <gazebo reference="front_left_head_light_link">
    <material>Gazebo/White</material>
  </gazebo>
  <gazebo reference="front_left_head_light_link">
    <material>Gazebo/White</material>
  </gazebo>
  <gazebo reference="front_left_turn_light_link">
    <material>Gazebo/Orange</material>
  </gazebo>
  <gazebo reference="front_right_turn_light_link">
    <material>Gazebo/Orange</material>
  </gazebo>
  <gazebo reference="left_I_link">
    <material>Gazebo/Orange</material>
  </gazebo>
  <gazebo reference="right_I_link">
    <material>Gazebo/Orange</material>
  </gazebo>
  <gazebo reference="left_blue_outer_link">
    <material>Gazebo/Blue</material>
  </gazebo>
  <gazebo reference="right_blue_outer_link">
    <material>Gazebo/Blue</material>
  </gazebo>
  <gazebo reference="left_antenna_link">
    <material>Gazebo/Grey</material>
  </gazebo>
  <gazebo reference="right_antenna_link">
    <material>Gazebo/Grey</material>
  </gazebo>
  <gazebo reference="rear_left_stop_light_link">
    <material>Gazebo/Red</material>
  </gazebo>
  <gazebo reference="rear_right_stop_light_link">
    <material>Gazebo/Red</material>
  </gazebo>
  <gazebo reference="front_single_camera_link">
    <material>Gazebo/Red</material>
  </gazebo>
  <gazebo reference="IMU_link">
    <material>Gazebo/Red</material>
  </gazebo>
  <gazebo reference="front_sonar_link">
    <material>Gazebo/Orange</material>
  </gazebo>
  <gazebo reference="rear_sonar_link">
    <material>Gazebo/Orange</material>
  </gazebo>
  <gazebo reference="stereo_camera_link">
    <material>Gazebo/Red</material>
  </gazebo>
  <gazebo>
    <plugin filename="libgazebo_ros_control.so" name="gazebo_ros_control">
      <legacyModeNS>true</legacyModeNS>
      <robotSimType>gazebo_ros_control/DefaultRobotHWSim</robotSimType>
    </plugin>
  </gazebo>
  <!-- **************************************** Need Modification Below *********************************************** -->
  <!-- camera -->
  <gazebo reference="front_single_camera_link">
    <sensor name="front_single_camera_sensor" type="camera">
      <update_rate>30.0</update_rate>
      <camera name="front_single_camera">
        <horizontal_fov>1.5707963</horizontal_fov>
        <image>
          <width>640</width>
          <height>480</height>
          <format>R8G8B8</format>
        </image>
        <clip>
          <near>0.02</near>
          <far>300</far>
        </clip>
        <noise>
          <type>gaussian</type>
          <mean>0.0</mean>
          <stddev>0.007</stddev>
        </noise>
      </camera>
      <plugin filename="libgazebo_ros_camera.so" name="front_single_camera_controller">
        <alwaysOn>true</alwaysOn>
        <updateRate>0.0</updateRate>
        <cameraName>gem/front_single_camera</cameraName>
        <imageTopicName>front_single_camera/image_raw</imageTopicName>
        <cameraInfoTopicName>gem/front_single_camera/camera_info</cameraInfoTopicName>
        <frameName>front_single_camera_link</frameName>
        <hackBaseline>0.07</hackBaseline>
        <distortionK1>0.0</distortionK1>
        <distortionK2>0.0</distortionK2>
        <distortionK3>0.0</distortionK3>
        <distortionT1>0.0</distortionT1>
        <distortionT2>0.0</distortionT2>
      </plugin>
    </sensor>
  </gazebo>
  <!-- IMU -->
  <gazebo>
    <plugin filename="libgazebo_ros_imu.so" name="imu_plugin">
      <alwaysOn>true</alwaysOn>
      <bodyName>IMU_link</bodyName>
      <frameName>IMU_link</frameName>
      <topicName>imu</topicName>
      <serviceName>imu_service</serviceName>
      <gaussianNoise>0.0</gaussianNoise>
      <updateRate>20.0</updateRate>
    </plugin>
  </gazebo>
  <!-- GPS -->
  <gazebo>
    <plugin filename="libhector_gazebo_ros_gps.so" name="gazebo_ros_gps">
      <updateRate>5.0</updateRate>
      <bodyName>GPS_link</bodyName>
      <frameId>GPS_link</frameId>
      <topicName>/gps/fix</topicName>
      <velocityTopicName>/gps/fix_velocity</velocityTopicName>
      <referenceLatitude>-30.06022459407145675</referenceLatitude>
      <referenceLongitude>-51.173913575780311191</referenceLongitude>
      <referenceHeading>90</referenceHeading>
      <referenceAltitude>10</referenceAltitude>
      <offset>0 0 0</offset>
      <drift>0.001 0.001 0.001</drift>
      <gaussianNoise>0.05 0.05 0.05</gaussianNoise>
      <velocityDrift>0.001 0.001 0.001</velocityDrift>
      <velocityGaussianNoise>0.5 0.5 0.5</velocityGaussianNoise>
      <!-- <drift>0.001 0.001 0.001</drift> -->
      <!-- <gaussianNoise>0.01 0.01 0.01</gaussianNoise> -->
      <!-- <velocityDrift>0 0 0</velocityDrift>-->
      <!-- <velocityGaussianNoise>0.05 0.05 0.05</velocityGaussianNoise> -->
    </plugin>
  </gazebo>
  <!-- Front Sonar -->
  <gazebo reference="front_sonar_link">
    <sensor name="front_sonar_sensor" type="ray">
      <always_on>true</always_on>
      <update_rate>10</update_rate>
      <pose>0 0 0 0 0 0</pose>
      <visualize>false</visualize>
      <ray>
        <scan>
          <horizontal>
            <samples>2</samples>
            <resolution>1</resolution>
            <min_angle>-28</min_angle>
            <max_angle>28</max_angle>
          </horizontal>
          <vertical>
            <samples>2</samples>
            <resolution>1</resolution>
            <min_angle>-28</min_angle>
            <max_angle>28</max_angle>
          </vertical>
        </scan>
        <range>
          <min>0.3</min>
          <max>5</max>
          <resolution>0.01</resolution>
        </range>
      </ray>
      <plugin filename="libhector_gazebo_ros_sonar.so" name="gazebo_ros_sonar_controller">
        <gaussianNoise>0.005</gaussianNoise>
        <topicName>/front_sonar_distance</topicName>
        <frameId>front_sonar_link</frameId>
      </plugin>
    </sensor>
  </gazebo>
  <!-- Rear Sonar -->
  <gazebo reference="rear_sonar_link">
    <sensor name="rear_sonar_sensor" type="ray">
      <always_on>true</always_on>
      <update_rate>10</update_rate>
      <pose>0 0 0 0 0 0</pose>
      <visualize>false</visualize>
      <ray>
        <scan>
          <horizontal>
            <samples>2</samples>
            <resolution>1</resolution>
            <min_angle>-28</min_angle>
            <max_angle>28</max_angle>
          </horizontal>
          <vertical>
            <samples>2</samples>
            <resolution>1</resolution>
            <min_angle>-28</min_angle>
            <max_angle>28</max_angle>
          </vertical>
        </scan>
        <range>
          <min>0.3</min>
          <max>5</max>
          <resolution>0.01</resolution>
        </range>
      </ray>
      <plugin filename="libhector_gazebo_ros_sonar.so" name="gazebo_ros_sonar_controller">
        <gaussianNoise>0.005</gaussianNoise>
        <topicName>/rear_sonar_distance</topicName>
        <frameId>rear_sonar_link</frameId>
      </plugin>
    </sensor>
  </gazebo>
  <!-- stereo camera -->
  <gazebo reference="stereo_camera_link">
    <sensor name="stereo_camera" type="multicamera">
      <update_rate>30.0</update_rate>
      <camera name="left">
        <horizontal_fov>1.5707963</horizontal_fov>
        <image>
          <width>800</width>
          <height>600</height>
          <format>R8G8B8</format>
        </image>
        <clip>
          <near>0.02</near>
          <far>300</far>
        </clip>
        <noise>
          <type>gaussian</type>
          <mean>0.0</mean>
          <stddev>0.007</stddev>
        </noise>
      </camera>
      <camera name="right">
        <pose>0 -0.07 0 0 0 0</pose>
        <horizontal_fov>1.5707963</horizontal_fov>
        <image>
          <width>800</width>
          <height>600</height>
          <format>R8G8B8</format>
        </image>
        <clip>
          <near>0.02</near>
          <far>300</far>
        </clip>
        <noise>
          <type>gaussian</type>
          <mean>0.0</mean>
          <stddev>0.007</stddev>
        </noise>
      </camera>
      <plugin filename="libgazebo_ros_multicamera.so" name="stereo_camera_controller">
        <alwaysOn>true</alwaysOn>
        <updateRate>0.0</updateRate>
        <cameraName>stereo/camera</cameraName>
        <imageTopicName>image_raw</imageTopicName>
        <cameraInfoTopicName>camera_info</cameraInfoTopicName>
        <frameName>stereo_camera_link</frameName>
        <!--<rightFrameName>right_camera_optical_frame</rightFrameName>-->
        <!-- <hackBaseline>0.07</hackBaseline> -->
        <hackBaseline>0.5</hackBaseline>
        <distortionK1>0.0</distortionK1>
        <distortionK2>0.0</distortionK2>
        <distortionK3>0.0</distortionK3>
        <distortionT1>0.0</distortionT1>
        <distortionT2>0.0</distortionT2>
      </plugin>
    </sensor>
  </gazebo>
  <!-- colors used by Rviz -->
  <material name="black">
    <color rgba="0.0 0.0 0.0 1.0"/>
  </material>
  <material name="blue">
    <color rgba="0 0 0.8 1.0"/>
  </material>
  <material name="green">
    <color rgba="0.0 0.8 0.0 1.0"/>
  </material>
  <material name="grey">
    <color rgba="0.2 0.2 0.2 1.0"/>
  </material>
  <material name="orange">
    <color rgba="1.0 0.4235294117647059 0.0392156862745098 1.0"/>
  </material>
  <material name="brown">
    <color rgba="0.8705882352941177 0.8117647058823529 0.7647058823529411 1.0"/>
  </material>
  <material name="red">
    <color rgba="0.8 0.0 0.0 1.0"/>
  </material>
  <material name="white">
    <color rgba="1.0 1.0 1.0 1.0"/>
  </material>
  <!-- transmission macros -->
  <link name="base_footprint"> 
  </link>
  <link name="base_link">
    <inertial>
      <origin rpy="0 0 0" xyz="0.0410109641324594 0.000349767124208047 0.219524161679779"/>
      <mass value="686.066668067387"/>
      <inertia ixx="205.702789313137" ixy="-0.20742120719075" ixz="-9.13771633467953" iyy="482.020173559149" iyz="0.0517191981605489" izz="482.316418870047"/>
    </inertial>
    <visual>
      <origin rpy="0 0 0" xyz="0 0 0"/>
      <geometry>
        <mesh filename="package://gem_description/meshes/base_link.STL"/>
      </geometry>
      <material name="white"/>
    </visual>
    <collision>
      <origin rpy="0 0 0" xyz="0 0 0"/>
      <geometry>
        <mesh filename="package://gem_description/meshes/base_link.STL"/>
      </geometry>
    </collision>
  </link>
  <joint name="base_link" type="fixed">
    <origin rpy="0 0 0" xyz="0 0 0.44"/>
    <parent link="base_footprint"/>
    <child link="base_link"/>
  </joint>
  <!-- ******************************************* Fixed links below ******************************************* -->
  <link name="chair_link">
    <inertial>
      <origin rpy="0 0 0" xyz="-0.25168177279603 0.000276944933646828 0.46906166648726"/>
      <mass value="66.2564411399325"/>
      <inertia ixx="14.0051678459864" ixy="-0.00120200191290221" ixz="1.77455776912037" iyy="7.60803819714354" iyz="0.000593044825837774" izz="9.70729216894754"/>
    </inertial>
    <visual>
      <origin rpy="0 0 0" xyz="0 0 0"/>
      <geometry>
        <mesh filename="package://gem_description/meshes/chair_link.STL"/>
      </geometry>
      <material name="grey"/>
    </visual>
    <collision>
      <origin rpy="0 0 0" xyz="0 0 0"/>
      <geometry>
        <mesh filename="package://gem_description/meshes/chair_link.STL"/>
      </geometry>
    </collision>
  </link>
  <joint name="chair_joint" type="fixed">
    <origin rpy="0 0 0" xyz="0.001 0 -0.02"/>
    <parent link="base_link"/>
    <child link="chair_link"/>
    <axis xyz="0 0 0"/>
  </joint>
  <link name="door_link">
    <inertial>
      <origin rpy="0 0 0" xyz="0.00621903196002507 5.84652914581429E-07 0.358550118826029"/>
      <mass value="62.4925124039456"/>
      <inertia ixx="27.8360789144871" ixy="1.83479416068222E-05" ixz="0.311750082296841" iyy="7.554911896405" iyz="-2.52231014544191E-05" izz="26.8975099460351"/>
    </inertial>
    <visual>
      <origin rpy="0 0 0" xyz="0 0 0"/>
      <geometry>
        <mesh filename="package://gem_description/meshes/door_link.STL"/>
      </geometry>
      <material name="white"/>
    </visual>
    <collision>
      <origin rpy="0 0 0" xyz="0 0 0"/>
      <geometry>
        <mesh filename="package://gem_description/meshes/door_link.STL"/>
      </geometry>
    </collision>
  </link>
  <joint name="door_joint" type="fixed">
    <origin rpy="0 0 0" xyz="0.001 0 -0.015"/>
    <parent link="base_link"/>
    <child link="door_link"/>
    <axis xyz="0 0 0"/>
  </joint>
  <link name="top_rack_link">
    <inertial>
      <origin rpy="0 0 0" xyz="0.169 0.0522767054778464 -0.657500000000002"/>
      <mass value="8.88367739999998"/>
      <inertia ixx="1.60728217120871" ixy="6.00084366111482E-18" ixz="-9.81342263314531E-17" iyy="1.72456661616785" iyz="-5.92489168501132E-16" izz="0.152983311828453"/>
    </inertial>
    <visual>
      <origin rpy="0 0 0" xyz="0 0 0"/>
      <geometry>
        <mesh filename="package://gem_description/meshes/top_rack_link.STL"/>
      </geometry>
      <material name="black"/>
    </visual>
    <collision>
      <origin rpy="0 0 0" xyz="0 0 0"/>
      <geometry>
        <mesh filename="package://gem_description/meshes/top_rack_link.STL"/>
      </geometry>
    </collision>
  </link>
  <joint name="top_rack_joint" type="fixed">
    <origin rpy="1.5708 0 3.1416" xyz="-0.10172 0.6575 1.3921"/>
    <parent link="base_link"/>
    <child link="top_rack_link"/>
    <axis xyz="0 0 0"/>
  </joint>
  <link name="front_rack_link">
    <inertial>
      <origin rpy="0 0 0" xyz="6.075819031226E-08 0.307874350591294 0.0128881009983504"/>
      <mass value="2.56587584103832"/>
      <inertia ixx="0.0399935403341327" ixy="3.94985201351379E-09" ixz="4.81783258455845E-09" iyy="0.17153401949232" iyz="-0.00251237710479529" izz="0.207040614168028"/>
    </inertial>
    <visual>
      <origin rpy="0 0 0" xyz="0 0 0"/>
      <geometry>
        <mesh filename="package://gem_description/meshes/front_rack_link.STL"/>
      </geometry>
      <material name="black"/>
    </visual>
    <collision>
      <origin rpy="0 0 0" xyz="0 0 0"/>
      <geometry>
        <mesh filename="package://gem_description/meshes/front_rack_link.STL"/>
      </geometry>
    </collision>
  </link>
  <joint name="front_rack_joint" type="fixed">
    <origin rpy="1.5708 0 1.5708" xyz="1.352 0 -0.30594"/>
    <parent link="base_link"/>
    <child link="front_rack_link"/>
    <axis xyz="0 0 0"/>
  </joint>
  <link name="rear_rack_link">
    <inertial>
      <origin rpy="0 0 0" xyz="6.1506188045457E-08 0.310150326128451 0.0147333533268064"/>
      <mass value="2.53467167075235"/>
      <inertia ixx="0.0382035938045769" ixy="4.30467478765709E-09" ixz="5.10550487033654E-09" iyy="0.170120841320212" iyz="-0.00163705466710053" izz="0.205257577869692"/>
    </inertial>
    <visual>
      <origin rpy="0 0 0" xyz="0 0 0"/>
      <geometry>
        <mesh filename="package://gem_description/meshes/rear_rack_link.STL"/>
      </geometry>
      <material name="black"/>
    </visual>
    <collision>
      <origin rpy="0 0 0" xyz="0 0 0"/>
      <geometry>
        <mesh filename="package://gem_description/meshes/rear_rack_link.STL"/>
      </geometry>
    </collision>
  </link>
  <joint name="rear_rack_joint" type="fixed">
    <origin rpy="1.5708 0 -1.5708" xyz="-1.302 0 -0.27168"/>
    <parent link="base_link"/>
    <child link="rear_rack_link"/>
    <axis xyz="0 0 0"/>
  </joint>
  <link name="front_right_head_light_link">
    <inertial>
      <origin rpy="0 0 0" xyz="0.0181463762919891 5.55111512312578E-17 3.5527136788005E-15"/>
      <mass value="0.269468017191218"/>
      <inertia ixx="0.000596868390925667" ixy="-4.5493541174505E-37" ixz="-8.43232887809658E-21" iyy="0.000330811799186419" iyz="2.38964055770904E-36" izz="0.00033081179918642"/>
    </inertial>
    <visual>
      <origin rpy="0 0 0" xyz="0 0 0"/>
      <geometry>
        <mesh filename="package://gem_description/meshes/front_right_head_light_link.STL"/>
      </geometry>
      <material name="white"/>
    </visual>
    <collision>
      <origin rpy="0 0 0" xyz="0 0 0"/>
      <geometry>
        <mesh filename="package://gem_description/meshes/front_right_head_light_link.STL"/>
      </geometry>
    </collision>
  </link>
  <joint name="front_right_head_light_joint" type="fixed">
    <origin rpy="0 0 0" xyz="0.755 -0.5 0.58706"/>
    <parent link="base_link"/>
    <child link="front_right_head_light_link"/>
    <axis xyz="1 0 0"/>
  </joint>
  <link name="front_left_head_light_link">
    <inertial>
      <origin rpy="0 0 0" xyz="0.0181463762919891 -1.11022302462516E-16 3.99680288865056E-15"/>
      <mass value="0.269468017191218"/>
      <inertia ixx="0.000596868390925667" ixy="-4.5493541174505E-37" ixz="-8.43232887809658E-21" iyy="0.000330811799186419" iyz="2.38964055770904E-36" izz="0.00033081179918642"/>
    </inertial>
    <visual>
      <origin rpy="0 0 0" xyz="0 0 0"/>
      <geometry>
        <mesh filename="package://gem_description/meshes/front_left_head_light_link.STL"/>
      </geometry>
      <material name="white"/>
    </visual>
    <collision>
      <origin rpy="0 0 0" xyz="0 0 0"/>
      <geometry>
        <mesh filename="package://gem_description/meshes/front_left_head_light_link.STL"/>
      </geometry>
    </collision>
  </link>
  <joint name="front_left_head_light_joint" type="fixed">
    <origin rpy="0 0 0" xyz="0.755 0.5 0.58706"/>
    <parent link="base_link"/>
    <child link="front_left_head_light_link"/>
    <axis xyz="1 0 0"/>
  </joint>
  <link name="front_right_turn_light_link">
    <inertial>
      <origin rpy="0 0 0" xyz="0.0135004225053658 0 3.99680288865056E-15"/>
      <mass value="0.065815901054829"/>
      <inertia ixx="4.78304226243906E-05" ixy="-4.43957359734856E-38" ixz="6.07038039167315E-22" iyy="2.82661732953809E-05" iyz="1.76248991828734E-37" izz="2.82661732953809E-05"/>
    </inertial>
    <visual>
      <origin rpy="0 0 0" xyz="0 0 0"/>
      <geometry>
        <mesh filename="package://gem_description/meshes/front_right_turn_light_link.STL"/>
      </geometry>
      <material name="orange"/>
    </visual>
    <collision>
      <origin rpy="0 0 0" xyz="0 0 0"/>
      <geometry>
        <mesh filename="package://gem_description/meshes/front_right_turn_light_link.STL"/>
      </geometry>
    </collision>
  </link>
  <joint name="front_right_turn_light_joint" type="fixed">
    <origin rpy="0 0 0" xyz="0.765 -0.345 0.58706"/>
    <parent link="base_link"/>
    <child link="front_right_turn_light_link"/>
    <axis xyz="1 0 0"/>
  </joint>
  <link name="front_left_turn_light_link">
    <inertial>
      <origin rpy="0 0 0" xyz="0.0135004225053658 0 3.99680288865056E-15"/>
      <mass value="0.065815901054829"/>
      <inertia ixx="4.78304226243906E-05" ixy="-4.43957359734856E-38" ixz="6.07038039167315E-22" iyy="2.82661732953809E-05" iyz="1.76248991828734E-37" izz="2.82661732953809E-05"/>
    </inertial>
    <visual>
      <origin rpy="0 0 0" xyz="0 0 0"/>
      <geometry>
        <mesh filename="package://gem_description/meshes/front_left_turn_light_link.STL"/>
      </geometry>
      <material name="orange"/>
    </visual>
    <collision>
      <origin rpy="0 0 0" xyz="0 0 0"/>
      <geometry>
        <mesh filename="package://gem_description/meshes/front_left_turn_light_link.STL"/>
      </geometry>
    </collision>
  </link>
  <joint name="front_left_turn_light_joint" type="fixed">
    <origin rpy="0 0 0" xyz="0.765 0.345 0.58706"/>
    <parent link="base_link"/>
    <child link="front_left_turn_light_link"/>
    <axis xyz="1 0 0"/>
  </joint>
  <link name="rear_right_light_link">
    <inertial>
      <origin rpy="0 0 0" xyz="-0.00499999999999989 -2.77555756156289E-17 -9.76996261670138E-15"/>
      <mass value="0.0318086256175967"/>
      <inertia ixx="3.22062334378166E-05" ixy="-1.38305597517403E-38" ixz="6.87334333960818E-36" iyy="1.6368188599055E-05" iyz="-1.39682298768093E-51" izz="1.6368188599055E-05"/>
    </inertial>
    <visual>
      <origin rpy="0 0 0" xyz="0 0 0"/>
      <geometry>
        <mesh filename="package://gem_description/meshes/rear_right_light_link.STL"/>
      </geometry>
      <material name="red"/>
    </visual>
    <collision>
      <origin rpy="0 0 0" xyz="0 0 0"/>
      <geometry>
        <mesh filename="package://gem_description/meshes/rear_right_light_link.STL"/>
      </geometry>
    </collision>
  </link>
  <joint name="rear_right_light_joint" type="fixed">
    <origin rpy="0 0 0" xyz="-1.195 -0.32 0.025063"/>
    <parent link="base_link"/>
    <child link="rear_right_light_link"/>
    <axis xyz="1 0 0"/>
  </joint>
  <link name="rear_left_light_link">
    <inertial>
      <origin rpy="0 0 0" xyz="-0.00499999999999989 0 -1.02140518265514E-14"/>
      <mass value="0.0318086256175967"/>
      <inertia ixx="3.22062334378166E-05" ixy="-1.38305597517403E-38" ixz="6.87334333960818E-36" iyy="1.6368188599055E-05" iyz="-1.39682298768093E-51" izz="1.6368188599055E-05"/>
    </inertial>
    <visual>
      <origin rpy="0 0 0" xyz="0 0 0"/>
      <geometry>
        <mesh filename="package://gem_description/meshes/rear_left_light_link.STL"/>
      </geometry>
      <material name="red"/>
    </visual>
    <collision>
      <origin rpy="0 0 0" xyz="0 0 0"/>
      <geometry>
        <mesh filename="package://gem_description/meshes/rear_left_light_link.STL"/>
      </geometry>
    </collision>
  </link>
  <joint name="rear_left_light_joint" type="fixed">
    <origin rpy="0 0 0" xyz="-1.195 0.32 0.025063"/>
    <parent link="base_link"/>
    <child link="rear_left_light_link"/>
    <axis xyz="1 0 0"/>
  </joint>
  <link name="rear_left_stop_light_link">
    <inertial>
      <origin rpy="0 0 0" xyz="0.00972430253262702 9.82547376793264E-15 -9.32587340685131E-15"/>
      <mass value="0.109202778987047"/>
      <inertia ixx="0.000190538645890679" ixy="6.45440196434648E-19" ixz="-3.41278961232262E-21" iyy="9.87843441608066E-05" iyz="-9.37294393995117E-36" izz="9.87843441608066E-05"/>
    </inertial>
    <visual>
      <origin rpy="0 0 0" xyz="0 0 0"/>
      <geometry>
        <mesh filename="package://gem_description/meshes/rear_left_stop_light_link.STL"/>
      </geometry>
      <material name="red"/>
    </visual>
    <collision>
      <origin rpy="0 0 0" xyz="0 0 0"/>
      <geometry>
        <mesh filename="package://gem_description/meshes/rear_left_stop_light_link.STL"/>
      </geometry>
    </collision>
  </link>
  <joint name="rear_left_stop_light_joint" type="fixed">
    <origin rpy="0 0 3.1416" xyz="-1.195 0.38 0.24506"/>
    <parent link="base_link"/>
    <child link="rear_left_stop_light_link"/>
    <axis xyz="1 0 0"/>
  </joint>
  <link name="rear_right_stop_light_link">
    <inertial>
      <origin rpy="0 0 0" xyz="0.00972430253262724 9.82547376793264E-15 -1.02140518265514E-14"/>
      <mass value="0.109202778987047"/>
      <inertia ixx="0.000190538645890679" ixy="6.45440196434648E-19" ixz="-3.41278961232262E-21" iyy="9.87843441608066E-05" iyz="-9.37294393995117E-36" izz="9.87843441608066E-05"/>
    </inertial>
    <visual>
      <origin rpy="0 0 0" xyz="0 0 0"/>
      <geometry>
        <mesh filename="package://gem_description/meshes/rear_right_stop_light_link.STL"/>
      </geometry>
      <material name="red"/>
    </visual>
    <collision>
      <origin rpy="0 0 0" xyz="0 0 0"/>
      <geometry>
        <mesh filename="package://gem_description/meshes/rear_right_stop_light_link.STL"/>
      </geometry>
    </collision>
  </link>
  <joint name="rear_right_stop_light_joint" type="fixed">
    <origin rpy="0 0 3.1416" xyz="-1.195 -0.38 0.24506"/>
    <parent link="base_link"/>
    <child link="rear_right_stop_light_link"/>
    <axis xyz="1 0 0"/>
  </joint>
  <link name="right_blue_outer_link">
    <inertial>
      <origin rpy="0 0 0" xyz="-5.55111512312578E-17 0.005 0"/>
      <mass value="0.104700000000001"/>
      <inertia ixx="0.00181327500000001" ixy="-5.27013311869779E-23" ixz="-2.77932685817817E-19" iyy="0.00257909140000001" iyz="-1.43496084528411E-21" izz="0.000767561400000003"/>
    </inertial>
    <visual>
      <origin rpy="0 0 0" xyz="0 0 0"/>
      <geometry>
        <mesh filename="package://gem_description/meshes/right_blue_outer_link.STL"/>
      </geometry>
      <material name="blue"/>
    </visual>
    <collision>
      <origin rpy="0 0 0" xyz="0 0 0"/>
      <geometry>
        <mesh filename="package://gem_description/meshes/right_blue_outer_link.STL"/>
      </geometry>
    </collision>
  </link>
  <joint name="right_blue_outer_joint" type="fixed">
    <origin rpy="0 0 0" xyz="0.002 -0.6745 0.23435"/>
    <parent link="base_link"/>
    <child link="right_blue_outer_link"/>
    <axis xyz="0 0 0"/>
  </joint>
  <link name="right_I_link">
    <inertial>
      <origin rpy="0 0 0" xyz="-5.55111512312578E-17 0.005 4.44089209850063E-16"/>
      <mass value="0.266"/>
      <inertia ixx="0.00324508333333333" ixy="2.86326238812301E-21" ixz="-9.03626747764308E-20" iyy="0.00398107733333333" iyz="-3.62249939950654E-37" izz="0.000740427333333333"/>
    </inertial>
    <visual>
      <origin rpy="0 0 0" xyz="0 0 0"/>
      <geometry>
        <mesh filename="package://gem_description/meshes/right_I_link.STL"/>
      </geometry>
      <material name="orange"/>
    </visual>
    <collision>
      <origin rpy="0 0 0" xyz="0 0 0"/>
      <geometry>
        <mesh filename="package://gem_description/meshes/right_I_link.STL"/>
      </geometry>
    </collision>
  </link>
  <joint name="right_I_joint" type="fixed">
    <origin rpy="0 0 0" xyz="0.002 -0.6745 0.23435"/>
    <parent link="base_link"/>
    <child link="right_I_link"/>
    <axis xyz="0 0 0"/>
  </joint>
  <link name="left_blue_outer_link">
    <inertial>
      <origin rpy="0 0 0" xyz="-5.55111512312578E-17 0.00500000000000012 0"/>
      <mass value="0.1047"/>
      <inertia ixx="0.00181327500000001" ixy="9.72940865559704E-23" ixz="-1.45583787809333E-19" iyy="0.00257909140000001" iyz="-1.84855115156062E-21" izz="0.000767561400000003"/>
    </inertial>
    <visual>
      <origin rpy="0 0 0" xyz="0 0 0"/>
      <geometry>
        <mesh filename="package://gem_description/meshes/left_blue_outer_link.STL"/>
      </geometry>
      <material name="blue"/>
    </visual>
    <collision>
      <origin rpy="0 0 0" xyz="0 0 0"/>
      <geometry>
        <mesh filename="package://gem_description/meshes/left_blue_outer_link.STL"/>
      </geometry>
    </collision>
  </link>
  <joint name="left_blue_outer_joint" type="fixed">
    <origin rpy="0 0 0" xyz="0.002 0.6645 0.23435"/>
    <parent link="base_link"/>
    <child link="left_blue_outer_link"/>
    <axis xyz="0 0 0"/>
  </joint>
  <link name="left_I_link">
    <inertial>
      <origin rpy="0 0 0" xyz="-2.77555756156289E-17 0.005 0"/>
      <mass value="0.266"/>
      <inertia ixx="0.00324508333333333" ixy="2.77201399922805E-21" ixz="6.69378600355003E-20" iyy="0.00398107733333333" iyz="-3.19843170187135E-23" izz="0.000740427333333332"/>
    </inertial>
    <visual>
      <origin rpy="0 0 0" xyz="0 0 0"/>
      <geometry>
        <mesh filename="package://gem_description/meshes/left_I_link.STL"/>
      </geometry>
      <material name="orange"/>
    </visual>
    <collision>
      <origin rpy="0 0 0" xyz="0 0 0"/>
      <geometry>
        <mesh filename="package://gem_description/meshes/left_I_link.STL"/>
      </geometry>
    </collision>
  </link>
  <joint name="left_I_joint" type="fixed">
    <origin rpy="0 0 0" xyz="0.002 0.6645 0.23435"/>
    <parent link="base_link"/>
    <child link="left_I_link"/>
    <axis xyz="0 0 0"/>
  </joint>
  <link name="right_antenna_link">
    <inertial>
      <origin rpy="0 0 0" xyz="-5.55111512312578E-17 2.44249065417534E-15 0.0121155822482986"/>
      <mass value="0.136416164800573"/>
      <inertia ixx="7.37368964618847E-05" ixy="-3.06109536749749E-37" ixz="-5.86182991414975E-22" iyy="7.37368964618847E-05" iyz="-1.11563872602674E-37" izz="0.000133877796554154"/>
    </inertial>
    <visual>
      <origin rpy="0 0 0" xyz="0 0 0"/>
      <geometry>
        <mesh filename="package://gem_description/meshes/right_antenna_link.STL"/>
      </geometry>
      <material name="grey"/>
    </visual>
    <collision>
      <origin rpy="0 0 0" xyz="0 0 0"/>
      <geometry>
        <mesh filename="package://gem_description/meshes/right_antenna_link.STL"/>
      </geometry>
    </collision>
  </link>
  <joint name="right_antenna_joint" type="fixed">
    <origin rpy="0 0 0" xyz="-0.23472 -0.6125 1.5071"/>
    <parent link="base_link"/>
    <child link="right_antenna_link"/>
    <axis xyz="0 0 1"/>
  </joint>
  <link name="left_antenna_link">
    <inertial>
      <origin rpy="0 0 0" xyz="-5.55111512312578E-17 2.44249065417534E-15 0.012115582248299"/>
      <mass value="0.136416164800573"/>
      <inertia ixx="7.37368964618847E-05" ixy="-3.06109536749744E-37" ixz="-5.57203300808161E-22" iyy="7.37368964618847E-05" iyz="-1.11563872602673E-37" izz="0.000133877796554154"/>
    </inertial>
    <visual>
      <origin rpy="0 0 0" xyz="0 0 0"/>
      <geometry>
        <mesh filename="package://gem_description/meshes/left_antenna_link.STL"/>
      </geometry>
      <material name="grey"/>
    </visual>
    <collision>
      <origin rpy="0 0 0" xyz="0 0 0"/>
      <geometry>
        <mesh filename="package://gem_description/meshes/left_antenna_link.STL"/>
      </geometry>
    </collision>
  </link>
  <joint name="left_antenna_joint" type="fixed">
    <origin rpy="0 0 0" xyz="-0.23472 0.6125 1.5071"/>
    <parent link="base_link"/>
    <child link="left_antenna_link"/>
    <axis xyz="0 0 1"/>
  </joint>
  <link name="rear_left_emergency_button_link">
    <inertial>
      <origin rpy="0 0 0" xyz="-1.11022302462516E-16 0.0126540837643514 2.66453525910038E-15"/>
      <mass value="0.0162466711659546"/>
      <inertia ixx="2.6298686963986E-06" ixy="1.03389842837371E-38" ixz="-9.08487993518231E-39" iyy="3.62977311979424E-06" iyz="-3.77300506598995E-23" izz="2.6298686963986E-06"/>
    </inertial>
    <visual>
      <origin rpy="0 0 0" xyz="0 0 0"/>
      <geometry>
        <mesh filename="package://gem_description/meshes/rear_left_emergency_button_link.STL"/>
      </geometry>
      <material name="red"/>
    </visual>
    <collision>
      <origin rpy="0 0 0" xyz="0 0 0"/>
      <geometry>
        <mesh filename="package://gem_description/meshes/rear_left_emergency_button_link.STL"/>
      </geometry>
    </collision>
  </link>
  <joint name="rear_left_emergency_button_joint" type="fixed">
    <origin rpy="0 0 0" xyz="-0.72012 0.6645 0.83815"/>
    <parent link="base_link"/>
    <child link="rear_left_emergency_button_link"/>
    <axis xyz="0 1 0"/>
  </joint>
  <link name="rear_right_emergency_button_link">
    <inertial>
      <origin rpy="0 0 0" xyz="1.11022302462516E-16 0.0126540837643516 0"/>
      <mass value="0.0162466711659548"/>
      <inertia ixx="2.62986869639873E-06" ixy="4.04185685485635E-21" ixz="-3.17637355220363E-22" iyy="3.6297731197944E-06" iyz="-6.32020341731348E-21" izz="2.62986869639873E-06"/>
    </inertial>
    <visual>
      <origin rpy="0 0 0" xyz="0 0 0"/>
      <geometry>
        <mesh filename="package://gem_description/meshes/rear_right_emergency_button_link.STL"/>
      </geometry>
      <material name="red"/>
    </visual>
    <collision>
      <origin rpy="0 0 0" xyz="0 0 0"/>
      <geometry>
        <mesh filename="package://gem_description/meshes/rear_right_emergency_button_link.STL"/>
      </geometry>
    </collision>
  </link>
  <joint name="rear_right_emergency_button_joint" type="fixed">
    <origin rpy="0 0.57871 3.1416" xyz="-0.72012 -0.6645 0.83815"/>
    <parent link="base_link"/>
    <child link="rear_right_emergency_button_link"/>
    <axis xyz="0 1 0"/>
  </joint>
  <link name="front_left_emergency_button_link">
    <inertial>
      <origin rpy="0 0 0" xyz="1.11022302462516E-16 0.0126540837643514 3.10862446895044E-15"/>
      <mass value="0.0162466711659546"/>
      <inertia ixx="2.6298686963986E-06" ixy="1.03389842837371E-38" ixz="-9.08487993518231E-39" iyy="3.62977311979424E-06" iyz="-3.77300506598995E-23" izz="2.6298686963986E-06"/>
    </inertial>
    <visual>
      <origin rpy="0 0 0" xyz="0 0 0"/>
      <geometry>
        <mesh filename="package://gem_description/meshes/front_left_emergency_button_link.STL"/>
      </geometry>
      <material name="red"/>
    </visual>
    <collision>
      <origin rpy="0 0 0" xyz="0 0 0"/>
      <geometry>
        <mesh filename="package://gem_description/meshes/front_left_emergency_button_link.STL"/>
      </geometry>
    </collision>
  </link>
  <joint name="front_left_emergency_button_joint" type="fixed">
    <origin rpy="0 0 0" xyz="1.1497 0.6645 0.20492"/>
    <parent link="base_link"/>
    <child link="front_left_emergency_button_link"/>
    <axis xyz="0 1 0"/>
  </joint>
  <link name="front_right_emergency_button_link">
    <inertial>
      <origin rpy="0 0 0" xyz="0 0.0126540837643517 -2.22044604925031E-16"/>
      <mass value="0.0162466711659548"/>
      <inertia ixx="2.62986869639873E-06" ixy="4.04185685485635E-21" ixz="-3.17637355220363E-22" iyy="3.6297731197944E-06" iyz="-6.32020341731347E-21" izz="2.62986869639873E-06"/>
    </inertial>
    <visual>
      <origin rpy="0 0 0" xyz="0 0 0"/>
      <geometry>
        <mesh filename="package://gem_description/meshes/front_right_emergency_button_link.STL"/>
      </geometry>
      <material name="red"/>
    </visual>
    <collision>
      <origin rpy="0 0 0" xyz="0 0 0"/>
      <geometry>
        <mesh filename="package://gem_description/meshes/front_right_emergency_button_link.STL"/>
      </geometry>
    </collision>
  </link>
  <joint name="front_right_emergency_button_joint" type="fixed">
    <origin rpy="0 0.57871 3.1416" xyz="1.1497 -0.6645 0.20492"/>
    <parent link="base_link"/>
    <child link="front_right_emergency_button_link"/>
    <axis xyz="0 1 0"/>
  </joint>
  <link name="front_camera_link">
    <inertial>
      <origin rpy="0 0 0" xyz="0 0 0"/>
      <mass value="0.07"/>
      <inertia ixx="0.000175820811714078" ixy="0.0" ixz="0.0" iyy="0.0" iyz="0.0" izz="0.00022282574207345"/>
    </inertial>
    <visual>
      <origin rpy="0 0 0" xyz="0 0 0"/>
      <geometry>
        <mesh filename="package://gem_description/meshes/front_camera_link.STL"/>
      </geometry>
      <material name="black"/>
    </visual>
    <collision>
      <origin rpy="0 0 0" xyz="0 0 0"/>
      <geometry>
        <mesh filename="package://gem_description/meshes/front_camera_link.STL"/>
      </geometry>
    </collision>
  </link>
  <joint name="front_camera_joint" type="fixed">
    <origin rpy="1.5708 0 -3.1416" xyz="0.16 -0.11 1.1063"/>
    <parent link="base_link"/>
    <child link="front_camera_link"/>
    <axis xyz="0 0 0"/>
  </joint>
  <link name="rear_light_bar_link">
    <inertial>
      <origin rpy="0 0 0" xyz="0 0 0"/>
      <mass value="0.0841360233382311"/>
      <inertia ixx="0.0" ixy="0.0" ixz="0.0" iyy="0.00103132903875222" iyz="0.0" izz="0.00103577957177912"/>
    </inertial>
    <visual>
      <origin rpy="0 0 0" xyz="0 0 0"/>
      <geometry>
        <mesh filename="package://gem_description/meshes/rear_light_bar_link.STL"/>
      </geometry>
      <material name="red"/>
    </visual>
    <collision>
      <origin rpy="0 0 0" xyz="0 0 0"/>
      <geometry>
        <mesh filename="package://gem_description/meshes/rear_light_bar_link.STL"/>
      </geometry>
    </collision>
  </link>
  <joint name="rear_light_bar_joint" type="fixed">
    <origin rpy="-1.9138 0 1.5708" xyz="-0.64921 0 0.76944"/>
    <parent link="base_link"/>
    <child link="rear_light_bar_link"/>
    <axis xyz="0 0 0"/>
  </joint>
  <!-- ******************************************* Fixed links above ******************************************* -->
  <!-- ***************************************** Wheel settings below ****************************************** -->
  <link name="left_steering_hinge_link">
    <inertial>
      <mass value="1"/>
      <origin rpy="0 0 0" xyz="0 0 0"/>
      <inertia ixx="0.004" ixy="0.0" ixz="0.0" iyy="0.004" iyz="0.0" izz="0.004"/>
    </inertial>
  </link>
  <joint name="left_steering_hinge_joint" type="revolute">
    <parent link="base_link"/>
    <child link="left_steering_hinge_link"/>
    <origin rpy="0 0 0" xyz="0.88 0.6 -0.151"/>
    <axis xyz="0 0 1"/>
    <limit effort="100" lower="-0.61" upper="0.61" velocity="0.5"/>
  </joint>
  <link name="front_left_wheel_link">
    <inertial>
      <mass value="11"/>
      <origin xyz="0 0 0"/>
      <inertia ixx="0.58631238" ixy="0.0" ixz="0.0" iyy="0.33552910" iyz="0.0" izz="0.33552910"/>
    </inertial>
    <visual>
      <origin rpy="0 0 0" xyz="0 0 0"/>
      <geometry>
        <mesh filename="package://gem_description/meshes/front_left_wheel_link.STL"/>
      </geometry>
      <material name="black"/>
    </visual>
    <collision name="front_left_wheel_collision">
      <geometry>
        <sphere radius="0.295"/>
      </geometry>
    </collision>
  </link>
  <joint name="front_left_wheel_joint" type="continuous">
    <parent link="left_steering_hinge_link"/>
    <child link="front_left_wheel_link"/>
    <origin rpy="0 0 0" xyz="0 0 0"/>
    <axis xyz="0 1 0"/>
    <limit effort="1000" velocity="100.0"/>
  </joint>
  <link name="right_steering_hinge_link">
    <inertial>
      <mass value="1"/>
      <origin rpy="0 0 0" xyz="0 0 0"/>
      <inertia ixx="0.004" ixy="0.0" ixz="0.0" iyy="0.004" iyz="0.0" izz="0.004"/>
    </inertial>
  </link>
  <joint name="right_steering_hinge_joint" type="revolute">
    <parent link="base_link"/>
    <child link="right_steering_hinge_link"/>
    <origin rpy="0 0 0" xyz="0.88 -0.6 -0.151"/>
    <axis xyz="0 0 1"/>
    <limit effort="100" lower="-0.61" upper="0.61" velocity="0.5"/>
  </joint>
  <link name="front_right_wheel_link">
    <inertial>
      <mass value="11"/>
      <origin xyz="0 0 0"/>
      <inertia ixx="0.58631238" ixy="0.0" ixz="0.0" iyy="0.33552910" iyz="0.0" izz="0.33552910"/>
    </inertial>
    <visual>
      <origin rpy="0 0 0" xyz="0 0 0"/>
      <geometry>
        <mesh filename="package://gem_description/meshes/front_right_wheel_link.STL"/>
      </geometry>
      <material name="black"/>
    </visual>
    <collision name="front_right_wheel_collision">
      <geometry>
        <sphere radius="0.295"/>
      </geometry>
    </collision>
  </link>
  <joint name="front_right_wheel_joint" type="continuous">
    <parent link="right_steering_hinge_link"/>
    <child link="front_right_wheel_link"/>
    <origin rpy="0 0 0" xyz="0 0 0"/>
    <axis xyz="0 1 0"/>
    <limit effort="1000" velocity="100.0"/>
  </joint>
  <link name="rear_left_wheel_link">
    <inertial>
      <mass value="11"/>
      <origin xyz="0 0 0"/>
      <inertia ixx="0.58631238" ixy="0.0" ixz="0.0" iyy="0.33552910" iyz="0.0" izz="0.33552910"/>
    </inertial>
    <visual>
      <origin rpy="0 0 0" xyz="0 0 0"/>
      <geometry>
        <mesh filename="package://gem_description/meshes/rear_left_wheel_link.STL"/>
      </geometry>
      <material name="black"/>
    </visual>
    <collision name="rear_left_wheel_collision">
      <geometry>
        <sphere radius="0.295"/>
      </geometry>
    </collision>
  </link>
  <joint name="rear_left_wheel_joint" type="continuous">
    <origin rpy="0 0 0" xyz="-0.87 0.6 -0.151"/>
    <parent link="base_link"/>
    <child link="rear_left_wheel_link"/>
    <axis xyz="0 1 0"/>
    <limit effort="1000.0" velocity="100.0"/>
  </joint>
  <link name="rear_right_wheel_link">
    <inertial>
      <mass value="11"/>
      <origin xyz="0 0 0"/>
      <inertia ixx="0.58631238" ixy="0.0" ixz="0.0" iyy="0.33552910" iyz="0.0" izz="0.33552910"/>
    </inertial>
    <visual>
      <origin rpy="0 0 0" xyz="0 0 0"/>
      <geometry>
        <mesh filename="package://gem_description/meshes/rear_right_wheel_link.STL"/>
      </geometry>
      <material name="black"/>
    </visual>
    <collision name="rear_right_wheel_collision">
      <geometry>
        <sphere radius="0.295"/>
      </geometry>
    </collision>
  </link>
  <joint name="rear_right_wheel_joint" type="continuous">
    <origin rpy="0 0 0" xyz="-0.87 -0.6 -0.151"/>
    <parent link="base_link"/>
    <child link="rear_right_wheel_link"/>
    <axis xyz="0 1 0"/>
    <limit effort="1000.0" velocity="100.0"/>
  </joint>
  <!-- ******************************************** Transmissions ********************************************* -->
  <transmission name="rear_left_wheel_transmission" type="SimpleTransmission">
    <type>transmission_interface/SimpleTransmission</type>
    <joint name="rear_left_wheel_joint">
      <hardwareInterface>hardware_interface/EffortJointInterface</hardwareInterface>
    </joint>
    <actuator name="rear_left_wheel_motor">
      <hardwareInterface>hardware_interface/EffortJointInterface</hardwareInterface>
      <mechanicalReduction>1</mechanicalReduction>
    </actuator>
  </transmission>
  <transmission name="rear_right_wheel_transmission" type="SimpleTransmission">
    <type>transmission_interface/SimpleTransmission</type>
    <joint name="rear_right_wheel_joint">
      <hardwareInterface>hardware_interface/EffortJointInterface</hardwareInterface>
    </joint>
    <actuator name="rear_right_wheel_motor">
      <hardwareInterface>hardware_interface/EffortJointInterface</hardwareInterface>
      <mechanicalReduction>1</mechanicalReduction>
    </actuator>
  </transmission>
  <transmission name="front_left_wheel_transmission" type="SimpleTransmission">
    <type>transmission_interface/SimpleTransmission</type>
    <joint name="front_left_wheel_joint">
      <hardwareInterface>hardware_interface/EffortJointInterface</hardwareInterface>
    </joint>
    <actuator name="front_left_wheel_motor">
      <hardwareInterface>hardware_interface/EffortJointInterface</hardwareInterface>
      <mechanicalReduction>1</mechanicalReduction>
    </actuator>
  </transmission>
  <transmission name="front_right_wheel_transmission" type="SimpleTransmission">
    <type>transmission_interface/SimpleTransmission</type>
    <joint name="front_right_wheel_joint">
      <hardwareInterface>hardware_interface/EffortJointInterface</hardwareInterface>
    </joint>
    <actuator name="front_right_wheel_motor">
      <hardwareInterface>hardware_interface/EffortJointInterface</hardwareInterface>
      <mechanicalReduction>1</mechanicalReduction>
    </actuator>
  </transmission>
  <transmission name="left_steering_hinge_transmission" type="SimpleTransmission">
    <type>transmission_interface/SimpleTransmission</type>
    <joint name="left_steering_hinge_joint">
      <hardwareInterface>hardware_interface/EffortJointInterface</hardwareInterface>
    </joint>
    <actuator name="left_steering_hinge_motor">
      <hardwareInterface>hardware_interface/EffortJointInterface</hardwareInterface>
      <mechanicalReduction>1</mechanicalReduction>
    </actuator>
  </transmission>
  <transmission name="right_steering_hinge_transmission" type="SimpleTransmission">
    <type>transmission_interface/SimpleTransmission</type>
    <joint name="right_steering_hinge_joint">
      <hardwareInterface>hardware_interface/EffortJointInterface</hardwareInterface>
    </joint>
    <actuator name="right_steering_hinge_motor">
      <hardwareInterface>hardware_interface/EffortJointInterface</hardwareInterface>
      <mechanicalReduction>1</mechanicalReduction>
    </actuator>
  </transmission>
  <!-- *********************************************** Sensors ************************************************ -->
  <joint name="velodyne_base_mount_joint" type="fixed">
    <origin rpy="1.5708 0 3.1416" xyz="0.02 0.115 -0.6575"/>
    <parent link="top_rack_link"/>
    <child link="velodyne_base_link"/>
  </joint>
  <link name="velodyne_base_link">
    <inertial>
      <mass value="0.83"/>
      <origin xyz="0 0 0.03585"/>
      <inertia ixx="0.000908059425" ixy="0" ixz="0" iyy="0.000908059425" iyz="0" izz="0.0011049624"/>
    </inertial>
    <visual>
      <geometry>
        <mesh filename="package://velodyne_description/meshes/VLP16_base_1.dae"/>
      </geometry>
    </visual>
    <visual>
      <geometry>
        <mesh filename="package://velodyne_description/meshes/VLP16_base_2.dae"/>
      </geometry>
    </visual>
    <collision>
      <origin rpy="0 0 0" xyz="0 0 0.03585"/>
      <geometry>
        <cylinder length="0.0717" radius="0.0516"/>
      </geometry>
    </collision>
  </link>
  <joint name="velodyne_base_scan_joint" type="fixed">
    <origin rpy="0 0 0" xyz="0 0 0.0377"/>
    <parent link="velodyne_base_link"/>
    <child link="velodyne"/>
  </joint>
  <link name="velodyne">
    <inertial>
      <mass value="0.01"/>
      <origin xyz="0 0 0"/>
      <inertia ixx="1e-7" ixy="0" ixz="0" iyy="1e-7" iyz="0" izz="1e-7"/>
    </inertial>
    <visual>
      <origin xyz="0 0 -0.0377"/>
      <geometry>
        <mesh filename="package://velodyne_description/meshes/VLP16_scan.dae"/>
      </geometry>
    </visual>
  </link>
  <!-- Gazebo requires the velodyne_gazebo_plugins package -->
  <gazebo reference="velodyne">
    <sensor name="velodyne-VLP16" type="ray">
      <pose>0 0 0 0 0 0</pose>
      <visualize>false</visualize>
      <update_rate>10</update_rate>
      <ray>
        <scan>
          <horizontal>
            <samples>440</samples>
            <resolution>1</resolution>
            <min_angle>-3.141592653589793</min_angle>
            <max_angle>3.141592653589793</max_angle>
          </horizontal>
          <vertical>
            <samples>16</samples>
            <resolution>1</resolution>
            <min_angle>-0.2617993877991494</min_angle>
            <max_angle> 0.2617993877991494</max_angle>
          </vertical>
        </scan>
        <range>
          <min>0.3</min>
          <max>131.0</max>
          <resolution>0.001</resolution>
        </range>
        <noise>
          <type>gaussian</type>
          <mean>0.0</mean>
          <stddev>0.0</stddev>
        </noise>
      </ray>
      <plugin filename="libgazebo_ros_velodyne_laser.so" name="gazebo_ros_laser_controller">
        <topicName>/velodyne_points</topicName>
        <frameName>velodyne</frameName>
        <min_range>0.9</min_range>
        <max_range>130.0</max_range>
        <gaussianNoise>0.008</gaussianNoise>
      </plugin>
    </sensor>
  </gazebo>
  <link name="front_single_camera_link">
    <collision>
      <origin rpy="0 0 0" xyz="0 0 0"/>
      <geometry>
        <box size="0.05 0.05 0.05"/>
      </geometry>
    </collision>
    <visual>
      <origin rpy="0 0 0" xyz="0 0 0"/>
      <geometry>
        <box size="0.05 0.05 0.05"/>
      </geometry>
      <material name="red"/>
    </visual>
    <inertial>
      <mass value="1e-5"/>
      <origin rpy="0 0 0" xyz="0 0 0"/>
      <inertia ixx="1e-6" ixy="0" ixz="0" iyy="1e-6" iyz="0" izz="1e-6"/>
    </inertial>
  </link>
  <joint name="gem_front_camera_joint" type="fixed">
    <origin rpy="-1.5708 3.1416 0" xyz="-0.045 0 0"/>
    <parent link="front_camera_link"/>
    <child link="front_single_camera_link"/>
  </joint>
  <!--
  <link name="stereo_camera_link">
    <collision>
      <origin xyz="0 0 0" rpy="0 0 0"/>
      <geometry>
        <box size="0.05 0.05 0.05"/>
      </geometry>
    </collision>
    <visual>
      <origin xyz="0 0 0" rpy="0 0 0"/>
      <geometry>
        <box size="0.05 0.05 0.05"/>
      </geometry>
      <material name="red"/>
    </visual>
    <inertial>
      <mass value="1e-5" />
      <origin xyz="0 0 0" rpy="0 0 0"/>
      <inertia ixx="1e-6" ixy="0" ixz="0" iyy="1e-6" iyz="0" izz="1e-6" />
    </inertial>
  </link>


  <joint name="gem_stereo_camera_joint" type="fixed">
    <origin xyz="-0.045 0 0" rpy="-1.5708 3.1416 0"/>
    <parent link="front_camera_link"/>
    <child link="stereo_camera_link"/>
  </joint>
  -->
  <!-- IMU -->
  <link name="IMU_link">
    <collision>
      <origin rpy="0 0 0" xyz="0 0 0"/>
      <geometry>
        <box size="0.1 0.1 0.1"/>
      </geometry>
    </collision>
    <visual>
      <origin rpy="0 0 0" xyz="0 0 0"/>
      <geometry>
        <box size="0.1 0.1 0.1"/>
      </geometry>
      <material name="red"/>
    </visual>
    <inertial>
      <origin rpy="0 0 0" xyz="0 0 0"/>
      <mass value="1"/>
      <inertia ixx="1.0" ixy="0.0" ixz="0.0" iyy="1.0" iyz="0.0" izz="1.0"/>
    </inertial>
  </link>
  <joint name="IMU_joint" type="fixed">
    <origin rpy="0 0 -1.5708" xyz="-0.246 0 0.05"/>
    <parent link="base_link"/>
    <child link="IMU_link"/>
  </joint>
  <!-- GPS -->
  <link name="GPS_link">
    <collision>
      <origin rpy="0 0 0" xyz="0 0 0"/>
      <geometry>
        <box size="0.1 0.1 0.1"/>
      </geometry>
    </collision>
    <visual>
      <origin rpy="0 0 0" xyz="0 0 0"/>
      <geometry>
        <box size="0.1 0.1 0.1"/>
      </geometry>
      <material name="red"/>
    </visual>
    <inertial>
      <origin rpy="0 0 0" xyz="0 0 0"/>
      <mass value="1"/>
      <inertia ixx="1.0" ixy="0.0" ixz="0.0" iyy="1.0" iyz="0.0" izz="1.0"/>
    </inertial>
  </link>
  <joint name="GPS_joint" type="fixed">
    <origin rpy="0 0 0" xyz="-0.246 0 0.05"/>
    <parent link="base_link"/>
    <child link="GPS_link"/>
  </joint>
  <!-- Front Sonar -->
  <link name="front_sonar_link">
    <inertial>
      <mass value="0.001"/>
      <origin rpy="0 0 0" xyz="0 0 0"/>
      <inertia ixx="0.000000017" ixy="0" ixz="0" iyy="0.000000017" iyz="0" izz="0.000000017"/>
    </inertial>
    <visual>
      <origin rpy="0 0 0" xyz="0 0 0"/>
      <geometry>
        <box size="0.05 0.2 0.1"/>
      </geometry>
      <material name="orange"/>
    </visual>
    <collision>
      <origin rpy="0 0 0" xyz="0 0 0"/>
      <geometry>
        <box size="0.05 0.2 0.1"/>
      </geometry>
    </collision>
  </link>
  <joint name="front_sonar_joint" type="fixed">
    <origin rpy="0 -1.5708 -1.5708" xyz="0 0.38 0.065"/>
    <parent link="front_rack_link"/>
    <child link="front_sonar_link"/>
  </joint>
  <!-- Rear Sonar -->
  <link name="rear_sonar_link">
    <inertial>
      <mass value="0.001"/>
      <origin rpy="0 0 0" xyz="0 0 0"/>
      <inertia ixx="0.000000017" ixy="0" ixz="0" iyy="0.000000017" iyz="0" izz="0.000000017"/>
    </inertial>
    <visual>
      <origin rpy="0 0 0" xyz="0 0 0"/>
      <geometry>
        <box size="0.05 0.2 0.1"/>
      </geometry>
      <material name="orange"/>
    </visual>
    <collision>
      <origin rpy="0 0 0" xyz="0 0 0"/>
      <geometry>
        <box size="0.05 0.2 0.1"/>
      </geometry>
    </collision>
  </link>
  <joint name="rear_sonar_joint" type="fixed">
    <origin rpy="0 -1.5708 -1.5708" xyz="0 0.38 0.065"/>
    <parent link="rear_rack_link"/>
    <child link="rear_sonar_link"/>
  </joint>
</robot>

